Workbook
Name _0128_ILOCOS_NORTE: CITY!$B$1:$X$1
Name _0129_ILOCOS_SUR: CITY!$B$2:$AI$2
Name _0133_LA_UNION: CITY!$B$3:$V$3
Name _0155_PANGASINAN: CITY!$B$4:$AW$4
Name _0209_BATANES: CITY!$B$5:$G$5
Name _0215_CAGAYAN: CITY!$B$6:$AD$6
Name _0231_ISABELA: CITY!$B$7:$AL$7
Name _0250_NUEVA_VIZCAYA: CITY!$B$8:$P$8
Name _0257_QUIRINO: CITY!$B$9:$G$9
Name _0308_BATAAN: CITY!$B$10:$M$10
Name _0314_BULACAN: CITY!$B$11:$Y$11
Name _0349_NUEVA_ECIJA: CITY!$B$12:$AG$12
Name _0354_PAMPANGA: CITY!$B$13:$W$13
Name _0369_TARLAC: CITY!$B$14:$S$14
Name _0371_ZAMBALES: CITY!$B$15:$O$15
Name _0377_AURORA: CITY!$B$16:$I$16
Name _0410_BATANGAS: CITY!$B$17:$AI$17
Name _0421_CAVITE: CITY!$B$18:$X$18
Name _0434_LAGUNA: CITY!$B$19:$AE$19
Name _0456_QUEZON: CITY!$B$20:$AP$20
Name _0458_RIZAL: CITY!$B$21:$O$21
Name _0505_ALBAY: CITY!$B$22:$S$22
Name _0516_CAMARINES_NORTE: CITY!$B$23:$M$23
Name _0517_CAMARINES_SUR: CITY!$B$24:$AL$24
Name _0520_CATANDUANES: CITY!$B$25:$L$25
Name _0541_MASBATE: CITY!$B$26:$V$26
Name _0562_SORSOGON: CITY!$B$27:$P$27
Name _0604_AKLAN: CITY!$B$28:$R$28
Name _0606_ANTIQUE: CITY!$B$29:$V$29
Name _0619_CAPIZ: CITY!$B$30:$R$30
Name _0630_ILOILO: CITY!$B$31:$AV$31
Name _0645_NEGROS_OCCIDENTAL: CITY!$B$33:$AI$33
Name _0679_GUIMARAS: CITY!$B$32:$F$32
Name _0712_BOHOL: CITY!$B$34:$AW$34
Name _0722_CEBU: CITY!$B$35:$BB$35
Name _0746_NEGROS_ORIENTAL: CITY!$B$37:$Z$37
Name _0761_SIQUIJOR: CITY!$B$36:$G$36
Name _0826_EASTERN_SAMAR: CITY!$B$38:$X$38
Name _0837_LEYTE: CITY!$B$39:$AR$39
Name _0848_NORTHERN_SAMAR: CITY!$B$40:$Y$40
Name _0860_SAMAR__WESTERN_SAMAR: CITY!$B$41:$XFD$41
Name _0860_SAMAR_WESTERN_SAMAR: CITY!$B$41:$AA$41
Name _0864_SOUTHERN_LEYTE: CITY!$B$42:$T$42
Name _0878_BILIRAN: CITY!$B$43:$I$43
Name _0972_ZAMBOANGA_DEL_NORTE: CITY!$B$44:$AB$44
Name _0973_ZAMBOANGA_DEL_SUR: CITY!$B$45:$AC$45
Name _0983_ZAMBOANGA_SIBUGAY: CITY!$B$46:$Q$46
Name _0997_CITY_OF_ISABELA: CITY!$B$47
Name _0997_CITY_OF_ISABELA__Not_a_Province: CITY!$B$47:$BE$47
Name _1013_BUKIDNON: CITY!$B$48:$W$48
Name _101301_BAUNGON: BARANGAY!$B$1094:$XFD$1094
Name _101302_DAMULOG: BARANGAY!$B$1098:$XFD$1098
Name _101303_DANGCAGAN: BARANGAY!$B$1099:$XFD$1099
Name _101304_DON_CARLOS: BARANGAY!$B$1100:$XFD$1100
Name _101305_IMPASUG_ONG: BARANGAY!$B$1101:$XFD$1101
Name _101306_KADINGILAN: BARANGAY!$B$1102:$XFD$1102
Name _101307_KALILANGAN: BARANGAY!$B$1103:$XFD$1103
Name _101308_KIBAWE: BARANGAY!$B$1104:$XFD$1104
Name _101309_KITAOTAO: BARANGAY!$B$1105:$XFD$1105
Name _101310_LANTAPAN: BARANGAY!$B$1106:$XFD$1106

Sheet Eligible Population
A1: Priority Group* | B1: Sub-Priority Group* | C1: Last_Name* | D1: First_Name* | E1: Middle_Name* | F1: Suffix | G1: Mobile number (format:9170123456)* | H1: Current_Residence:_Region* | I1: Current_Residence: Province* | J1: Current_Residence: Municipality/City* | K1: Current_Residence: Barangay* | L1: Sex* | M1: Birthdate_mm/dd/yyyy_* | N1: Occupation* | O1: Allergy to vaccines or components of vaccines* | P1: With_Comorbidity?* | Q1: Email* | R1: Employee Number*

Sheet Key
A1: Categories | B1: Category_ID | C1: Sex | D1: Civil_Status | E1: Employment_Status | F1: With_Allergy? | G1: Name_of_Allergy | H1: With_Comorbidity? | I1: Patient_was_diagnosed_with_COVID_19 | J1: Provided_Consent? | K1: COVID_19_Classification | L1: Pregnancy | M1: Breastfeeding | N1: Role | O1: Profession | P1: Directly_in_interaction_with_COVID_patient | Q1: Name_of_Comorbidity | S1: Code | T1: Description | V1: CODE | W1: PROVINCE | X1: FINAL_PROVINCE | Y1: CODE | Z1: CITY | AA1: FINAL_CITY | AB1: CODE | AC1: BARANGAY | AD1: FINAL_BARANGAY | AF1: Reason_for_Refusal | AG1: Reason_for_Not_FIT | AH1: Vaccine Manufacturer | AI1: 1st Dose | AJ1: 2nd Dose | AK1: Bakuna center id
A2: 01_Health_Care_Worker | B2: 01_PRC_number | C2: 01_Female | D2: 01_Single | E2: 01_Government_Employed | F2: 01_Yes | G2: 01_Drug | H2: 01_Yes | I2: 01_Yes | J2: 01_Yes | K2: 01_Asymptomatic | L2: 01_Pregnant | M2: Yes_ | N2: Team_Lead | O2: 01_Dental_Hygienist | P2: 01_Yes | Q2: 01_Hypertension | S2: 175301 | T2: ABORLAN | U2: 175301_ABORLAN | V2: 1339 | W2: NCR,_CITY_OF_MANILA,_FIRST_DISTRICT_Not_a_Province) | X2: =CONCATENATE(V2," - ",W2) -> 1339 - NCR,_CITY_OF_MANILA,_FIRST_DISTRICT_Not_a_Province) | Y2: 137501 | Z2: CALOOCAN_CITY | AA2: =CONCATENATE(Y2," - ",Z2) -> 137501 - CALOOCAN_CITY | AB2: 133901001 | AC2: BARANGAY_1 | AD2: =CONCATENATE(AB2," - ",AC2) -> 133901001 - BARANGAY_1 | AF2: I do not think this vaccine is safe | AG2: Fever | AH2: Pfizer | AI2: 01_Yes | AJ2: 01_Yes | AK2: CBC000000000004211
A3: 02_Senior_Citizen | B3: 02_OSCA_number | C3: 02_Male | D3: 02_Married | E3: 02_Private_Employed | F3: 02_None | G3: 02_Food | H3: 02_None | I3: 02_No | J3: 02_No | K3: 02_Mild | L3: 02_Not_Pregnant | M3: No | N3: Counseling_Nurse | O3: 02_Dental_Technologist | P3: 02_No | Q3: 02_Heart_disease | S3: 1401 | T3: ABRA | U3: 1401_ABRA | V3: 1374 | W3: NCR,_SECOND_DISTRICT_(Not_a_Province) | X3: =CONCATENATE(V3," - ",W3) -> 1374 - NCR,_SECOND_DISTRICT_(Not_a_Province) | Y3: 137601 | Z3: CITY_OF_LAS_PIÑAS | AA3: =CONCATENATE(Y3," - ",Z3) -> 137601 - CITY_OF_LAS_PIÑAS | AB3: 133901002 | AC3: BARANGAY_2 | AD3: =CONCATENATE(AB3," - ",AC3) -> 133901002 - BARANGAY_2 | AF3: I do not think this vaccine is effective | AG3: Headache | AH3: Astrazeneca | AI3: 02_No | AJ3: 02_No | AK3: CBC000000000001886
A4: 03_Indigent | B4: 03_Facility_ID_number | D4: 03_Widow/Widower | E4: 03_Self_employed | G4: 03_Insect | I4: 00_UNKNOWN | K4: 03_Moderate | L4: 00_UNKNOWN | N4: Encoder | O4: 03_Dentist | P4: 00_UNKNOWN | Q4: 03_Kidney_disease | S4: 175101 | T4: ABRA_DE_ILOG | U4: =CONCATENATE(S4," - ",T4) -> 175101 - ABRA_DE_ILOG | V4: 1375 | W4: NCR,_THIRD_DISTRICT_(Not_a_Province) | X4: =CONCATENATE(V4," - ",W4) -> 1375 - NCR,_THIRD_DISTRICT_(Not_a_Province) | Y4: 137602 | Z4: CITY_OF_MAKATI | AA4: =CONCATENATE(Y4," - ",Z4) -> 137602 - CITY_OF_MAKATI | AB4: 133901003 | AC4: BARANGAY_3 | AD4: =CONCATENATE(AB4," - ",AC4) -> 133901003 - BARANGAY_3 | AF4: I do not trust a vaccine that has come from another country | AG4: Cough | AH4: Sinovac | AI4: 00_UNKNOWN | AJ4: 00_UNKNOWN | AK4: CBC000000000001113
A5: 04_Uniformed_Personnel | B5: 04_Other_ID | D5: 04_Separated/Annulled | E5: 04_Private_practitioner | G5: 04_Latex | K5: 04_Severe | O5: 04_Medical_Technologist | Q5: 04_Diabetes_mellitus | S5: 30801 | T5: ABUCAY | U5: =CONCATENATE(S5," - ",T5) -> 30801 - ABUCAY | V5: 1376 | W5: NCR,_FOURTH_DISTRICT_(Not_a_Province) | X5: =CONCATENATE(V5," - ",W5) -> 1376 - NCR,_FOURTH_DISTRICT_(Not_a_Province) | Y5: 137502 | Z5: CITY_OF_MALABON | AA5: =CONCATENATE(Y5," - ",Z5) -> 137502 - CITY_OF_MALABON | AB5: 133901004 | AC5: BARANGAY_4 | AD5: =CONCATENATE(AB5," - ",AC5) -> 133901004 - BARANGAY_4 | AF5: I have religious beliefs that do not allow me to be vaccinated | AG5: Colds | AK5: CBC000000000002742
A6: 05_Essential_Worker | B6: 00_UNKNOWN | D6: 05_Living_with_Partner | E6: 05_Others | G6: 05_Mold | K6: 05_Critical | O6: 05_Midwife | Q6: 05_Bronchial_Asthma | S6: 21501 | T6: ABULUG | U6: =CONCATENATE(S6," - ",T6) -> 21501 - ABULUG | X6: =CONCATENATE(V6," - ",W6) -> - | Y6: 137401 | Z6: CITY_OF_MANDALUYONG | AA6: =CONCATENATE(Y6," - ",Z6) -> 137401 - CITY_OF_MANDALUYONG | AB6: 133901005 | AC6: BARANGAY_5 | AD6: =CONCATENATE(AB6," - ",AC6) -> 133901005 - BARANGAY_5 | AF6: Others | AG6: Sore Throat | AK6: CBC000000000000495
A7: 06_Other | G7: 06_Pet | K7: 00_UNKNOWN | O7: 06_Nurse | Q7: 06_Immunodeficiency_state* | S7: 83701 | T7: ABUYOG | U7: =CONCATENATE(S7," - ",T7) -> 83701 - ABUYOG | X7: =CONCATENATE(V7," - ",W7) -> - | Y7: 133900 | Z7: CITY_OF_MANILA | AA7: =CONCATENATE(Y7," - ",Z7) -> 133900 - CITY_OF_MANILA | AB7: 133901006 | AC7: BARANGAY_6 | AD7: =CONCATENATE(AB7," - ",AC7) -> 133901006 - BARANGAY_6 | AG7: Shortness of Breath or Difficulty in Breathing | AK7: CBC000000000001090
A8: 07_Comorbidities | G8: 07_Pollen | O8: 07_Nutritionist_Dietician | Q8: 07_Cancer | S8: 12801 | T8: ADAMS | U8: =CONCATENATE(S8," - ",T8) -> 12801 - ADAMS | Y8: 137402 | Z8: CITY_OF_MARIKINA | AA8: =CONCATENATE(Y8," - ",Z8) -> 137402 - CITY_OF_MARIKINA | AB8: 133901007 | AC8: BARANGAY_7 | AD8: =CONCATENATE(AB8," - ",AC8) -> 133901007 - BARANGAY_7 | AG8: Chest Pain | AK8: CBC000000000003181
A9: 08_Teachers_Social_Workers | O9: 08_Occupational_Therapist | Q9: 08_Others | S9: 45601 | T9: AGDANGAN | U9: =CONCATENATE(S9," - ",T9) -> 45601 - AGDANGAN | Y9: 137603 | Z9: CITY_OF_MUNTINLUPA | AA9: =CONCATENATE(Y9," - ",Z9) -> 137603 - CITY_OF_MUNTINLUPA | AB9: 133901008 | AC9: BARANGAY_8 | AD9: =CONCATENATE(AB9," - ",AC9) -> 133901008 - BARANGAY_8 | AG9: Abdominal Pain | AK9: CBC000000000001890
A10: 09_Other_Govt_Wokers | O10: 09_Optometrist | S10: 25701 | T10: AGLIPAY | U10: =CONCATENATE(S10," - ",T10) -> 25701 - AGLIPAY | Y10: 137503 | Z10: CITY_OF_NAVOTAS | AA10: =CONCATENATE(Y10," - ",Z10) -> 137503 - CITY_OF_NAVOTAS | AB10: 133901009 | AC10: BARANGAY_9 | AD10: =CONCATENATE(AB10," - ",AC10) -> 133901009 - BARANGAY_9 | AG10: Changes in Bowel Movement | AK10: CBC000000000001855
A11: 10_Other_High_Risk | O11: 10_Pharmacist | S11: 15501 | T11: AGNO | U11: =CONCATENATE(S11," - ",T11) -> 15501 - AGNO | Y11: 137604 | Z11: CITY_OF_PARAÑAQUE | AA11: =CONCATENATE(Y11," - ",Z11) -> 137604 - CITY_OF_PARAÑAQUE | AB11: 133901010 | AC11: BARANGAY_10 | AD11: =CONCATENATE(AB11," - ",AC11) -> 133901010 - BARANGAY_10 | AG11: Loss of taste/smell | AK11: CBC000000000003544
A12: 11_OFW | O12: 11_Physical_Therapist | S12: 41001 | T12: AGONCILLO | U12: =CONCATENATE(S12," - ",T12) -> 41001 - AGONCILLO | Y12: 137403 | Z12: CITY_OF_PASIG | AA12: =CONCATENATE(Y12," - ",Z12) -> 137403 - CITY_OF_PASIG | AB12: 133901011 | AC12: BARANGAY_11 | AD12: =CONCATENATE(AB12," - ",AC12) -> 133901011 - BARANGAY_11 | AG12: Fatigue/weakness | AK12: CBC000000000001063
A13: 12_Remaining_Workforce | O13: 12_Physician | S13: 13301 | T13: AGOO | U13: =CONCATENATE(S13," - ",T13) -> 13301 - AGOO | Y13: 137405 | Z13: CITY_OF_SAN_JUAN | AA13: =CONCATENATE(Y13," - ",Z13) -> 137405 - CITY_OF_SAN_JUAN | AB13: 133901012 | AC13: BARANGAY_12 | AD13: =CONCATENATE(AB13," - ",AC13) -> 133901012 - BARANGAY_12 | AG13: COVID-19 in the past 90 days? | AK13: CBC000000000004142
A14: 00_UNKNOWN | O14: 13_Radiologic_Technologist | S14: 15502 | T14: AGUILAR | U14: =CONCATENATE(S14," - ",T14) -> 15502 - AGUILAR | Y14: 137504 | Z14: CITY_OF_VALENZUELA | AA14: =CONCATENATE(Y14," - ",Z14) -> 137504 - CITY_OF_VALENZUELA | AB14: 133901013 | AC14: BARANGAY_13 | AD14: =CONCATENATE(AB14," - ",AC14) -> 133901013 - BARANGAY_13 | AG14: Bleeding disorder or blood thinner | AK14: CBC000000000004222
O15: 14_Respiratory_Therapist | S15: 142708 | T15: AGUINALDO | U15: =CONCATENATE(S15," - ",T15) -> 142708 - AGUINALDO | Y15: 137605 | Z15: PASAY_CITY | AA15: =CONCATENATE(Y15," - ",Z15) -> 137605 - PASAY_CITY | AB15: 133901014 | AC15: BARANGAY_14 | AD15: =CONCATENATE(AB15," - ",AC15) -> 133901014 - BARANGAY_14 | AG15: Autoimmune disorder, HIV, AIDS, Cancer | AK15: CBC000000000003619
O16: 15_X_ray_Technologist | S16: 1602 | T16: AGUSAN_DEL_NORTE | U16: =CONCATENATE(S16," - ",T16) -> 1602 - AGUSAN_DEL_NORTE | Y16: 137606 | Z16: PATEROS | AA16: =CONCATENATE(Y16," - ",Z16) -> 137606 - PATEROS | AB16: 133901015 | AC16: BARANGAY_15 | AD16: =CONCATENATE(AB16," - ",AC16) -> 133901015 - BARANGAY_15 | AG16: Received any vaccine 4 weeks ago | AK16: CBC000000000003957
O17: 16_Barangay_Health_Worker | S17: 1603 | T17: AGUSAN_DEL_SUR | U17: =CONCATENATE(S17," - ",T17) -> 1603 - AGUSAN_DEL_SUR | Y17: 137404 | Z17: QUEZON_CITY | AA17: =CONCATENATE(Y17," - ",Z17) -> 137404 - QUEZON_CITY | AB17: 133901016 | AC17: BARANGAY_16 | AD17: =CONCATENATE(AB17," - ",AC17) -> 133901016 - BARANGAY_16 | AG17: Reaction from any previous vaccine? | AK17: CBC000000000004907
O18: 17_Maintenance_Staff | S18: 175302 | T18: AGUTAYA | U18: =CONCATENATE(S18," - ",T18) -> 175302 - AGUTAYA | Y18: 137607 | Z18: TAGUIG_CITY | AA18: =CONCATENATE(Y18," - ",Z18) -> 137607 - TAGUIG_CITY | AB18: 133901017 | AC18: BARANGAY_17 | AD18: =CONCATENATE(AB18," - ",AC18) -> 133901017 - BARANGAY_17 | AG18: Pregnant, Breastfeeding, Planning Pregnancy | AK18: CBC000000000002629
C19: Priority Group* | D19: Sub-Priority Group* | O19: 18_Administrative_Staff | S19: 63001 | T19: AJUY | U19: =CONCATENATE(S19," - ",T19) -> 63001 - AJUY | AA19: =CONCATENATE(Y19," -",Z19) -> - | AB19: 133901018 | AC19: BARANGAY_18 | AD19: =CONCATENATE(AB19," - ",AC19) -> 133901018 - BARANGAY_18 | AG19: Multiple conditions | AK19: CBC000000000005250
C20: 01_A1: Health Care Workers | D20: 01_A1.1: COVID-19 Referral Hospitals | O20: 19_Others_ | S20: 150708 | T20: AKBAR | U20: =CONCATENATE(S20," - ",T20) -> 150708 - AKBAR | AA20: =CONCATENATE(Y20," -",Z20) -> - | AB20: 133901019 | AC20: BARANGAY_19 | AD20: =CONCATENATE(AB20," - ",AC20) -> 133901019 - BARANGAY_19 | AG20: Hypertension | AK20: CBC000000000000891
C21: 02_A2: Senior Citizens | D21: 02_A1.2: Hopitals Catering to C19 Cases | S21: 604 | T21: AKLAN | U21: =CONCATENATE(S21," - ",T21) -> 604 - AKLAN | AA21: =CONCATENATE(Y21," -",Z21) -> - | AB21: 133901020 | AC21: BARANGAY_20 | AD21: =CONCATENATE(AB21," - ",AC21) -> 133901020 - BARANGAY_20 | AG21: 00_UNKNOWN | AK21: CBC000000000004542
A22: Suffix | C22: 03_A3: Adult with Comorbidity | D22: 03_A1.3: Quarantine Isolation Facilities | S22: 150709 | T22: AL_BARKA | U22: =CONCATENATE(S22," - ",T22) -> 150709 - AL_BARKA | AA22: =CONCATENATE(Y22," -",Z22) -> - | AB22: 133901025 | AC22: BARANGAY_25 | AD22: =CONCATENATE(AB22," - ",AC22) -> 133901025 - BARANGAY_25 | AK22: CBC000000000005510
A23: I | C23: 04_A4: Frontline Personnel in Essential Sector | D23: 04_A1.4: Remaining Hospitals | S23: 45602 | T23: ALABAT | U23: =CONCATENATE(S23," - ",T23) -> 45602 - ALABAT | AA23: =CONCATENATE(Y23," -",Z23) -> - | AB23: 133901026 | AC23: BARANGAY_26 | AD23: =CONCATENATE(AB23," - ",AC23) -> 133901026 - BARANGAY_26 | AK23: CBC000000000003063
A24: II | C24: 05_A5: Poor Population | D24: 05_A1.5: Government Owned Community Based Primary Care Facilities | S24: 128001 | T24: ALABEL_ | U24: =CONCATENATE(S24," - ",T24) -> 128001 - ALABEL_ | AA24: =CONCATENATE(Y24," -",Z24) -> - | AB24: 133901028 | AC24: BARANGAY_28 | AD24: =CONCATENATE(AB24," - ",AC24) -> 133901028 - BARANGAY_28 | AK24: CBC000000000004693
A25: III | C25: 06_B1: Teachers and Social Workers | D25: 06_A1.6: Stand-alone Clinics and Diagnostics | S25: 124701 | T25: ALAMADA | U25: =CONCATENATE(S25," - ",T25) -> 124701 - ALAMADA | AA25: =CONCATENATE(Y25," -",Z25) -> - | AB25: 133901029 | AC25: BARANGAY_29 | AD25: =CONCATENATE(AB25," - ",AC25) -> 133901029 - BARANGAY_29 | AK25: CBC000000000005545
A26: IV | C26: 07_B2: Other Government Workers | D26: 07_A1.7: Closed Settings and Institutions | S26: 43401 | T26: ALAMINOS | U26: =CONCATENATE(S26," - ",T26) -> 43401 - ALAMINOS | AA26: =CONCATENATE(Y26," -",Z26) -> - | AB26: 133901030 | AC26: BARANGAY_30 | AD26: =CONCATENATE(AB26," - ",AC26) -> 133901030 - BARANGAY_30 | AK26: CBC000000000000064
A27: JR | C27: 08_B3: Other Essential Workers | S27: 83702 | T27: ALANGALANG | U27: =CONCATENATE(S27," - ",T27) -> 83702 - ALANGALANG | AA27: =CONCATENATE(Y27," -",Z27) -> - | AB27: 133901031 | AC27: BARANGAY_31 | AD27: =CONCATENATE(AB27," - ",AC27) -> 133901031 - BARANGAY_31 | AK27: CBC000000000002933
A28: NA | C28: 09_B4: Socio-demographic Groups | S28: 505 | T28: ALBAY | U28: =CONCATENATE(S28," - ",T28) -> 505 - ALBAY | AA28: =CONCATENATE(Y28," -",Z28) -> - | AB28: 133901032 | AC28: BARANGAY_32 | AD28: =CONCATENATE(AB28," - ",AC28) -> 133901032 - BARANGAY_32 | AK28: CBC000000000002775
A29: SR | C29: 10_B5: Overseas Filipino Workers | S29: 83703 | T29: ALBUERA | U29: =CONCATENATE(S29," - ",T29) -> 83703 - ALBUERA | AA29: =CONCATENATE(Y29," -",Z29) -> - | AB29: 133901033 | AC29: BARANGAY_33 | AD29: =CONCATENATE(AB29," - ",AC29) -> 133901033 - BARANGAY_33 | AK29: CBC000000000003001
A30: V | C30: 11_B6: Other Remaing Workforce | S30: 71201 | T30: ALBURQUERQUE | U30: =CONCATENATE(S30," - ",T30) -> 71201 - ALBURQUERQUE | AA30: =CONCATENATE(Y30," -",Z30) -> - | AB30: 133901034 | AC30: BARANGAY_34 | AD30: =CONCATENATE(AB30," - ",AC30) -> 133901034 - BARANGAY_34 | AK30: CBC000000000003647
A31: 00_UNKNOWN | C31: 12_C: Rest of the Population | S31: 15504 | T31: ALCALA | U31: =CONCATENATE(S31," - ",T31) -> 15504 - ALCALA | AA31: =CONCATENATE(Y31," -",Z31) -> - | AB31: 133901035 | AC31: BARANGAY_35 | AD31: =CONCATENATE(AB31," - ",AC31) -> 133901035 - BARANGAY_35 | AK31: CBC000000000001718
S32: 21502 | T32: ALCALA | U32: =CONCATENATE(S32," - ",T32) -> 21502 - ALCALA | AA32: =CONCATENATE(Y32," -",Z32) -> - | AB32: 133901036 | AC32: BARANGAY_36 | AD32: =CONCATENATE(AB32," - ",AC32) -> 133901036 - BARANGAY_36 | AK32: CBC000000000005125
S33: 72201 | T33: ALCANTARA | U33: =CONCATENATE(S33," - ",T33) -> 72201 - ALCANTARA | AA33: =CONCATENATE(Y33," -",Z33) -> - | AB33: 133901037 | AC33: BARANGAY_37 | AD33: =CONCATENATE(AB33," - ",AC33) -> 133901037 - BARANGAY_37 | AK33: CBC000000000003897
S34: 175901 | T34: ALCANTARA | U34: =CONCATENATE(S34," - ",T34) -> 175901 - ALCANTARA | AA34: =CONCATENATE(Y34," -",Z34) -> - | AB34: 133901038 | AC34: BARANGAY_38 | AD34: =CONCATENATE(AB34," - ",AC34) -> 133901038 - BARANGAY_38 | AK34: CBC000000000001199
S35: 72202 | T35: ALCOY | U35: =CONCATENATE(S35," - ",T35) -> 72202 - ALCOY | AA35: =CONCATENATE(Y35," -",Z35) -> - | AB35: 133901039 | AC35: BARANGAY_39 | AD35: =CONCATENATE(AB35," - ",AC35) -> 133901039 - BARANGAY_39 | AK35: CBC000000000002732
S36: 72203 | T36: ALEGRIA | U36: =CONCATENATE(S36," - ",T36) -> 72203 - ALEGRIA | AA36: =CONCATENATE(Y36," -",Z36) -> - | AB36: 133901041 | AC36: BARANGAY_41 | AD36: =CONCATENATE(AB36," - ",AC36) -> 133901041 - BARANGAY_41 | AK36: CBC000000000001893
S37: 166701 | T37: ALEGRIA | U37: =CONCATENATE(S37," - ",T37) -> 166701 - ALEGRIA | AA37: =CONCATENATE(Y37," -",Z37) -> - | AB37: 133901042 | AC37: BARANGAY_42 | AD37: =CONCATENATE(AB37," - ",AC37) -> 133901042 - BARANGAY_42 | AK37: CBC000000000002516
S38: 124717 | T38: ALEOSAN | U38: =CONCATENATE(S38," - ",T38) -> 124717 - ALEOSAN | AA38: =CONCATENATE(Y38," -",Z38) -> - | AB38: 133901043 | AC38: BARANGAY_43 | AD38: =CONCATENATE(AB38," - ",AC38) -> 133901043 - BARANGAY_43 | AK38: CBC000000000002873
S39: 42101 | T39: ALFONSO | U39: =CONCATENATE(S39," - ",T39) -> 42101 - ALFONSO | AA39: =CONCATENATE(Y39," -",Z39) -> - | AB39: 133901044 | AC39: BARANGAY_44 | AD39: =CONCATENATE(AB39," - ",AC39) -> 133901044 - BARANGAY_44 | AK39: CBC000000000005299
S40: 25015 | T40: ALFONSO_CASTANEDA | U40: =CONCATENATE(S40," - ",T40) -> 25015 - ALFONSO_CASTANEDA | AA40: =CONCATENATE(Y40," -",Z40) -> - | AB40: 133901045 | AC40: BARANGAY_45 | AD40: =CONCATENATE(AB40," - ",AC40) -> 133901045 - BARANGAY_45 | AK40: CBC000000000001956
...

Sheet Vaccinators
A1: NAME_OF_FACILITY_ | B1: PRC_LICENSE_NUMBER | C1: LAST_NAME | D1: FIRST_NAME | E1: MIDDLE_NAME_ | F1: POSITION | G1: ROLE
H2: (team_lead,counseling_nurse,encoder)

Sheet READ ME
A1: Updates
A2: 44255 | B2: Added new Categories in Column A
A3: 44260 | B3: Reduced the Columns to be filled out
A4: 44260 | B4: Added 'others' in reason for refusal
A5: 44260 | B5: Added 'multiple reasons' for reason for deferral
A6: 44263 | B6: Added "I" in the suffix
A10: Guidelines
A11: 44260 | B11: Per NVOC Advisory #15, please submit the completed line list at 11am and 6pm daily
B12: Submit to the following link: | D12: http://bit.ly/VIMSVASupload
A13: 44260 | B13: Use the Bakuna Center ID and name from CBCR

Sheet Region
D2: Region | F2: Region
D3: Ilocos | F3: 01_Ilocos
D4: CagayanValley | F4: 02_Cagayan_Valley
D5: CentralLuzon | F5: 03_Central_Luzon
D6: CALABARZON | F6: 04_CALABARZON
D7: BicolRegion | F7: 05_Bicol_Region
D8: WesternVisayas | F8: 06_Western_Visayas
D9: CentralVisayas | F9: 07_Central_Visayas
D10: EasternVisayas | F10: 08_Eastern_Visayas
D11: ZamboangaPeninsula | F11: 09_Zamboanga_Peninsula
D12: NorthernMindanao | F12: 10_Northern_Mindanao
D13: DavaoRegion | F13: 11_Davao_Region
... D19: MIMAROPA | F19: 17_MIMAROPA

Sheet Province References
A1: cagayan_province
A2: 0209 | B2: BATANES | C2: =CONCATENATE("_",A2,"_",B2) -> _0209_BATANES | F2: =C2 -> _0209_BATANES | H2: =E2 -> 0
A3: 0215 | B3: CAGAYAN | C3: =CONCATENATE("_",A3,"_",B3) -> _0215_CAGAYAN | F3: =C3 -> _0215_CAGAYAN | H3: =E3 -> 0
A4: 0231 | B4: ISABELA | C4: =CONCATENATE("_",A4,"_",B4) -> _0231_ISABELA | F4: =C4 -> _0231_ISABELA | H4: =E4 -> 0
A5: 0250 | B5: NUEVA_VIZCAYA | C5: =CONCATENATE("_",A5,"_",B5) -> _0250_NUEVA_VIZCAYA | F5: =C5 -> _0250_NUEVA_VIZCAYA | H5: =E5 -> 0
A6: 0257 | B6: QUIRINO | C6: =CONCATENATE("_",A6,"_",B6) -> _0257_QUIRINO | F6: =C6 -> _0257_QUIRINO | H6: =E6 -> 0
A7: Central_Luzon
A8: 0308 | B8: BATAAN | C8: =CONCATENATE("_",'Province References'!A8,"_",B8) -> _0308_BATAAN
A9: 0314 | B9: BULACAN | C9: =CONCATENATE("_",'Province References'!A9,"_",B9) -> _0314_BULACAN
A10: 0349 | B10: NUEVA_ECIJA | C10: =CONCATENATE("_",'Province References'!A10,"_",B10) -> _0349_NUEVA_ECIJA
A11: 0354 | B11: PAMPANGA | C11: =CONCATENATE("_",'Province References'!A11,"_",B11) -> _0354_PAMPANGA
A12: 0369 | B12: TARLAC | C12: =CONCATENATE("_",'Province References'!A12,"_",B12) -> _0369_TARLAC
A13: 0371 | B13: ZAMBALES | C13: =CONCATENATE("_",'Province References'!A13,"_",B13) -> _0371_ZAMBALES
A14: 0377 | B14: AURORA | C14: =CONCATENATE("_",'Province References'!A14,"_",B14) -> _0377_AURORA
A15: Calabarzon
A16: 0410 | B16: BATANGAS | C16: =CONCATENATE("_",A16,"_",B16) -> _0410_BATANGAS
A17: 0421 | B17: CAVITE | C17: =CONCATENATE("_",A17,"_",B17) -> _0421_CAVITE
A18: 0434 | B18: LAGUNA | C18: =CONCATENATE("_",A18,"_",B18) -> _0434_LAGUNA
A19: 0456 | B19: QUEZON | C19: =CONCATENATE("_",A19,"_",B19) -> _0456_QUEZON
A20: 0458 | B20: RIZAL | C20: =CONCATENATE("_",A20,"_",B20) -> _0458_RIZAL
A21: BICOL
A22: 0505 | B22: ALBAY | C22: =CONCATENATE("_",A22,"_",B22) -> _0505_ALBAY | E22: =CONCATENATE(A22," - ",B22) -> 0505 - ALBAY | F22: =CONCATENATE(B22," - ",C22) -> ALBAY - _0505_ALBAY | G22: =CONCATENATE(C22," - ",D22) -> _0505_ALBAY - | H22: =CONCATENATE(D22," - ",E22) -> - 0505 - ALBAY | I22: =CONCATENATE(E22," - ",F22) -> 0505 - ALBAY - ALBAY - _0505_ALBAY | J22: =CONCATENATE(F22," - ",G22) -> ALBAY - _0505_ALBAY - _0505_ALBAY - | K22: =CONCATENATE(G22," - ",H22) -> _0505_ALBAY - - - 0505 - ALBAY
A23: 0516 | B23: CAMARINES_NORTE | C23: =CONCATENATE("_",A23,"_",B23) -> _0516_CAMARINES_NORTE
A24: 0517 | B24: CAMARINES_SUR | C24: =CONCATENATE("_",A24,"_",B24) -> _0517_CAMARINES_SUR
A25: 0520 | B25: CATANDUANES | C25: =CONCATENATE("_",A25,"_",B25) -> _0520_CATANDUANES
A26: 0541 | B26: MASBATE | C26: =CONCATENATE("_",A26,"_",B26) -> _0541_MASBATE
A27: 0562 | B27: SORSOGON | C27: =CONCATENATE("_",A27,"_",B27) -> _0562_SORSOGON
A29: WESTERN
A30: 0604 | B30: AKLAN | C30: =CONCATENATE("_",A30,"_",B30) -> _0604_AKLAN
A31: 0606 | B31: ANTIQUE | C31: =CONCATENATE("_",A31,"_",B31) -> _0606_ANTIQUE
A32: 0619 | B32: CAPIZ | C32: =CONCATENATE("_",A32,"_",B32) -> _0619_CAPIZ
A33: 0630 | B33: ILOILO | C33: =CONCATENATE("_",A33,"_",B33) -> _0630_ILOILO
A34: 0679 | B34: GUIMARAS | C34: =CONCATENATE("_",A34,"_",B34) -> _0679_GUIMARAS
A35: 0645 | B35: NEGROS_OCCIDENTAL | C35: =CONCATENATE("_",A35,"_",B35) -> _0645_NEGROS_OCCIDENTAL
A37: CENTRAL_VISAYAS
A38: 0712 | B38: BOHOL | C38: =CONCATENATE("_",A38,"_",B38) -> _0712_BOHOL
A39: 0722 | B39: CEBU | C39: =CONCATENATE("_",A39,"_",B39) -> _0722_CEBU
A40: 0761 | B40: SIQUIJOR | C40: =CONCATENATE("_",A40,"_",B40) -> _0761_SIQUIJOR
A41: 0746 | B41: NEGROS_ORIENTAL | C41: =CONCATENATE("_",A41,"_",B41) -> _0746_NEGROS_ORIENTAL
A43: EASTERN_VISAYAS
...

Sheet Province
A1: 01_Ilocos | B1: 02_Cagayan_Valley | C1: 03_Central_Luzon | D1: 04_CALABARZON | E1: 05_Bicol_Region | F1: 06_Western_Visayas | G1: 07_Central_Visayas | H1: 08_Eastern_Visayas | I1: 09_Zamboanga_Peninsula | J1: 10_Northern_Mindanao | K1: 11_Davao_Region | L1: 12_Soccsksargen | M1: 13_National_Capital_Region | N1: 14_Cordillera_Administrative_Region | O1: 15_Bangsamoro_Autonomous_Region_in_Muslim_Mindanao | P1: 16_CARAGA | Q1: 17_MIMAROPA
A2: 0128_ILOCOS_NORTE | B2: A | C2: E | D2: I | E2: M | F2: Q | G2: U | H2: Y | I2: CC | J2: GG | K2: KK | L2: OO | M2: SS | N2: WW | O2: AAA | P2: EEE | Q2: III
A3: 0129_ILOCOS_SUR | B3: B | C3: F | D3: J | E3: N | F3: R | G3: V | H3: Z | I3: DD | J3: HH | K3: LL | L3: PP | M3: TT | N3: XX | O3: BBB | P3: FFF | Q3: JJJ
A4: 0133_LA_UNION | B4: C | C4: G | D4: K | E4: O | F4: S | G4: W | H4: AA | I4: EE | J4: II | K4: MM | L4: QQ | M4: UU | N4: YY | O4: CCC | P4: GGG | Q4: KKK
A5: 0155_PANGASINAN | B5: D | C5: H | D5: L | E5: P | F5: T | G5: X | H5: BB | I5: FF | J5: JJ | K5: NN | L5: RR | M5: VV | N5: ZZ | O5: DDD | P5: HHH | Q5: LLL
A9: Ilocos | B9: _0128_ILOCOS_NORTE | C9: _0129_ILOCOS_SUR | D9: _0133_LA_UNION | E9: _0155_PANGASINAN
A10: CagayanValley | B10: _0209_BATANES | C10: _0215_CAGAYAN | D10: _0231_ISABELA | E10: _0250_NUEVA_VIZCAYA | F10: _0257_QUIRINO
A11: CentralLuzon | B11: _0308_BATAAN | C11: _0314_BULACAN | D11: _0349_NUEVA_ECIJA | E11: _0354_PAMPANGA | F11: _0369_TARLAC | G11: _0371_ZAMBALES | H11: _0377_AURORA
A12: CALABARZON | B12: _0410_BATANGAS | C12: _0421_CAVITE | D12: _0434_LAGUNA | E12: _0456_QUEZON | F12: _0458_RIZAL
A13: BicolRegion | B13: _0505_ALBAY | C13: _0516_CAMARINES_NORTE | D13: _0517_CAMARINES_SUR | E13: _0520_CATANDUANES | F13: _0541_MASBATE | G13: _0562_SORSOGON
A14: WesternVisayas | B14: _0604_AKLAN | C14: _0606_ANTIQUE | D14: _0619_CAPIZ | E14: _0630_ILOILO | F14: _0679_GUIMARAS | G14: _0645_NEGROS_OCCIDENTAL
A15: CentralVisayas | B15: _0712_BOHOL | C15: _0722_CEBU | D15: _0761_SIQUIJOR | E15: _0746_NEGROS_ORIENTAL
A16: EasternVisayas | B16: _0826_EASTERN_SAMAR | C16: _0837_LEYTE | D16: _0848_NORTHERN_SAMAR | E16: _0860_SAMAR_WESTERN_SAMAR | F16: _0864_SOUTHERN_LEYTE | G16: _0878_BILIRAN
A17: ZamboangaPeninsula | B17: _0972_ZAMBOANGA_DEL_NORTE | C17: _0973_ZAMBOANGA_DEL_SUR | D17: _0983_ZAMBOANGA_SIBUGAY | E17: _0997_CITY_OF_ISABELA
A18: NorthernMindanao | B18: _1013_BUKIDNON | C18: _1018_CAMIGUIN | D18: _1035_LANAO_DEL_NORTE | E18: _1042_MISAMIS_OCCIDENTAL | F18: _1043_MISAMIS_ORIENTAL
A19: DavaoRegion | B19: _1123_DAVAO_DEL_NORTE | C19: _1124_DAVAO_DEL_SUR | D19: _1125_DAVAO_ORIENTAL | E19: _1182_COMPOSTELA_VALLEY | F19: _1186_DAVAO_OCCIDENTAL
A20: Soccsksargen | B20: _1247_NORTH_COTABATO | C20: _1263_SOUTH_COTABATO | D20: _1265_SULTAN_KUDARAT | E20: _1280_SARANGANI | F20: _1298_COTABATO_CITY
A21: NationalCapitalRegion | B21: _1339_NCR_CITY_OF_MANILA_FIRST_DISTRICT | C21: _1374_NCR_SECOND_DISTRICT | D21: _1375_NCR_THIRD_DISTRICT | E21: _1376_NCR_FOURTH_DISTRICT
A22: CordilleraAdministrativeRegion | B22: _1401_ABRA | C22: _1411_BENGUET | D22: _1427_IFUGAO | E22: _1432_KALINGA | F22: _1444_MOUNTAIN_PROVINCE | G22: _1481_APAYAO
A23: BangsamoroAutonomousRegioninMuslimMindanao | B23: _1507_BASILAN | C23: _1536_LANAO_DEL_SUR | D23: _1538_MAGUINDANAO | E23: _1566_SULU | F23: _1570_TAWI_TAWI
A24: CARAGA | B24: _1602_AGUSAN_DEL_NORTE | C24: _1603_AGUSAN_DEL_SUR | D24: _1667_SURIGAO_DEL_NORTE | E24: _1668_SURIGAO_DEL_SUR | F24: _1685_DINAGAT_ISLANDS
A25: MIMAROPA | B25: _1740_MARINDUQUE | C25: _1751_OCCIDENTAL_MINDORO | D25: _1752_ORIENTAL_MINDORO | E25: _1753_PALAWAN | F25: _1759_ROMBLON
B27: _0128_ILOCOS_NORTE | C27: _0129_ILOCOS_SUR | D27: _0133_LA_UNION | E27: _0155_PANGASINAN
B28: _0209_BATANES | C28: _0215_CAGAYAN | D28: _0231_ISABELA | E28: _0250_NUEVA_VIZCAYA | F28: _0257_QUIRINO
B29: _0308_BATAAN | C29: _0314_BULACAN | D29: _0349_NUEVA_ECIJA | E29: _0354_PAMPANGA | F29: _0369_TARLAC | G29: _0371_ZAMBALES | H29: _0377_AURORA
B30: _0410_BATANGAS | C30: _0421_CAVITE | D30: _0434_LAGUNA | E30: _0456_QUEZON | F30: _0458_RIZAL
B31: _0505_ALBAY | C31: _0516_CAMARINES_NORTE | D31: _0517_CAMARINES_SUR | E31: _0520_CATANDUANES | F31: _0541_MASBATE | G31: _0562_SORSOGON
B32: _0604_AKLAN | C32: _0606_ANTIQUE | D32: _0619_CAPIZ | E32: _0630_ILOILO | F32: _0679_GUIMARAS | G32: _0645_NEGROS_OCCIDENTAL
B33: _0712_BOHOL | C33: _0722_CEBU | D33: _0761_SIQUIJOR | E33: _0746_NEGROS_ORIENTAL
B34: _0826_EASTERN_SAMAR | C34: _0837_LEYTE | D34: _0848_NORTHERN_SAMAR | E34: _0860_SAMAR_WESTERN_SAMAR | F34: _0864_SOUTHERN_LEYTE | G34: _0878_BILIRAN
B35: _0972_ZAMBOANGA_DEL_NORTE | C35: _0973_ZAMBOANGA_DEL_SUR | D35: _0983_ZAMBOANGA_SIBUGAY | E35: _0997_CITY_OF_ISABELA_(Not_a_Province)
B36: _1013_BUKIDNON | C36: _1018_CAMIGUIN | D36: _1035_LANAO_DEL_NORTE | E36: _1042_MISAMIS_OCCIDENTAL | F36: _1043_MISAMIS_ORIENTAL
B37: _1123_DAVAO_DEL_NORTE | C37: _1124_DAVAO_DEL_SUR | D37: _1125_DAVAO_ORIENTAL | E37: _1182_COMPOSTELA_VALLEY | F37: _1186_DAVAO_OCCIDENTAL
B38: _1247_COTABATO_(NORTH_COTABATO) | C38: _1263_SOUTH_COTABATO | D38: _1265_SULTAN_KUDARAT | E38: _1280_SARANGANI | F38: _1298_COTABATO_CITY_(Not_a_Province)
B39: _1339_NCR,_CITY_OF_MANILA,_FIRST_DISTRICT_(Not_a_Province) | C39: _1374_NCR,_SECOND_DISTRICT_(Not_a_Province) | D39: _1375_NCR,_THIRD_DISTRICT_(Not_a_Province) | E39: NCR,_FOURTH_DISTRICT_(Not_a_Province)
B40: _1401_ABRA | C40: _1411_BENGUET | D40: _1427_IFUGAO | E40: _1432_KALINGA | F40: _1444_MOUNTAIN_PROVINCE | G40: _1481_APAYAO
B41: _1507_BASILAN | C41: _1536_LANAO_DEL_SUR | D41: _1538_MAGUINDANAO | E41: _1566_SULU | F41: _1570_TAWI_TAWI
B42: _1602_AGUSAN_DEL_NORTE | C42: _1603_AGUSAN_DEL_SUR | D42: _1667_SURIGAO_DEL_NORTE | E42: _1668_SURIGAO_DEL_SUR | F42: _1685_DINAGAT_ISLANDS
B43: _1740_MARINDUQUE | C43: _1751_OCCIDENTAL_MINDORO | D43: _1752_ORIENTAL_MINDORO | E43: _1753_PALAWAN | F43: _1759_ROMBLON

Sheet bakuna center
A1: _1401_ABRA | B1: _1602_AGUSAN_DEL_NORTE | C1: _0604_AKLAN | D1: _0505_ALBAY | E1: _0606_ANTIQUE | F1: _1481_APAYAO | G1: _0377_AURORA | H1: _1507_BASILAN | I1: _0308_BATAAN | J1: _0209_BATANES | K1: _0410_BATANGAS | L1: _1411_BENGUET | M1: _0878_BILIRAN | N1: _0712_BOHOL | O1: _1013_BUKIDNON | P1: _0314_BULACAN | Q1: _0215_CAGAYAN | R1: _0516_CAMARINES_NORTE | S1: _0517_CAMARINES_SUR | T1: _1018_CAMIGUIN | U1: _0619_CAPIZ | V1: _0520_CATANDUANES | W1: _0421_CAVITE | X1: _0722_CEBU | Y1: _0997_CITY_OF_ISABELA | Z1: _1247_NORTH_COTABATO | AA1: _1298_COTABATO_CITY | AB1: _1182_COMPOSTELA_VALLEY | AC1: _1123_DAVAO_DEL_NORTE | AD1: _1124_DAVAO_DEL_SUR | AE1: _1186_DAVAO_OCCIDENTAL | AF1: _1125_DAVAO_ORIENTAL | AG1: _1685_DINAGAT_ISLANDS | AH1: _0826_EASTERN_SAMAR | AI1: _0679_GUIMARAS | AJ1: _1427_IFUGAO | AK1: _0128_ILOCOS_NORTE | AL1: _0129_ILOCOS_SUR | AM1: _0630_ILOILO | AN1: _0231_ISABELA | AO1: _1432_KALINGA | AP1: _0133_LA_UNION | AQ1: _0434_LAGUNA | AR1: _1035_LANAO_DEL_NORTE | AS1: _1536_LANAO_DEL_SUR | AT1: _0837_LEYTE | AU1: _1538_MAGUINDANAO | AV1: _1740_MARINDUQUE | AW1: _0541_MASBATE | AX1: _1042_MISAMIS_OCCIDENTAL | AY1: _1043_MISAMIS_ORIENTAL | AZ1: _1444_MOUNTAIN_PROVINCE | BA1: _1339_NCR_CITY_OF_MANILA_FIRST_DISTRICT | BB1: _1374_NCR_SECOND_DISTRICT | BC1: _1375_NCR_THIRD_DISTRICT | BD1: _1376_NCR_FOURTH_DISTRICT | BE1: _0645_NEGROS_OCCIDENTAL | BF1: _0746_NEGROS_ORIENTAL | BG1: _0848_NORTHERN_SAMAR | BH1: _0349_NUEVA_ECIJA | BI1: _0250_NUEVA_VIZCAYA | BJ1: _1751_OCCIDENTAL_MINDORO | BK1: _1752_ORIENTAL_MINDORO | BL1: _1753_PALAWAN | BM1: _0354_PAMPANGA | BN1: _0155_PANGASINAN | BO1: _0456_QUEZON | BP1: _0257_QUIRINO | BQ1: _0458_RIZAL | BR1: _1759_ROMBLON | BS1: _0860_SAMAR_WESTERN_SAMAR | BT1: _1280_SARANGANI | BU1: _0761_SIQUIJOR | BV1: _0562_SORSOGON | BW1: _1263_SOUTH_COTABATO | BX1: _0864_SOUTHERN_LEYTE | BY1: _1265_SULTAN_KUDARAT | BZ1: _1566_SULU | CA1: _1667_SURIGAO_DEL_NORTE | CB1: _1668_SURIGAO_DEL_SUR | CC1: _0369_TARLAC | CD1: _1570_TAWI_TAWI | CE1: _0371_ZAMBALES | CF1: _0972_ZAMBOANGA_DEL_NORTE | CG1: _0973_ZAMBOANGA_DEL_SUR | CH1: _0983_ZAMBOANGA_SIBUGAY
A2: CBC000000000003619 | B2: CBC000000000002202 | C2: CBC000000000003441 | D2: CBC000000000002053 | E2: CBC000000000004715 | F2: CBC000000000004646 | G2: CBC000000000003166 | H2: CBC000000000004144 | I2: CBC000000000003152 | J2: CBC000000000001956 | K2: CBC000000000005414 | L2: CBC000000000003654 | M2: CBC000000000005051 | N2: CBC000000000000033 | O2: CBC000000000001890 | P2: CBC000000000002752 | Q2: CBC000000000004907 | R2: CBC000000000001924 | S2: CBC000000000000958 | T2: CBC000000000001496 | U2: CBC000000000004220 | V2: CBC000000000001063 | W2: CBC000000000003551 | X2: CBC000000000001090 | Y2: CBC000000000005409 | Z2: CBC000000000002040 | AA2: CBC000000000002128 | AB2: CBC000000000002868 | AC2: CBC000000000002013 | AD2: CBC000000000002742 | AE2: CBC000000000002606 | AF2: CBC000000000004528 | AG2: CBC000000000001077 | AH2: CBC000000000003750 | AI2: CBC000000000005492 | AJ2: CBC000000000005431 | AK2: CBC000000000000064 | AL2: CBC000000000000164 | AM2: CBC000000000004082 | AN2: CBC000000000002933 | AO2: CBC000000000005299 | AP2: CBC000000000005257 | AQ2: CBC000000000004991 | AR2: CBC000000000001199 | AS2: CBC000000000004443 | AT2: CBC000000000003957 | AU2: CBC000000000004222 | AV2: CBC000000000004694 | AW2: CBC000000000001735 | AX2: CBC000000000002408 | AY2: CBC000000000005521 | AZ2: CBC000000000002775 | BA2: CBC000000000001611 | BB2: CBC000000000003001 | BC2: CBC000000000000495 | BD2: CBC000000000003063 | BE2: CBC000000000003544 | BF2: CBC000000000004542 | BG2: CBC000000000005545 | BH2: CBC000000000003181 | BI2: CBC000000000002629 | BJ2: CBC000000000005281 | BK2: CBC000000000005372 | BL2: CBC000000000004142 | BM2: CBC000000000004943 | BN2: CBC000000000002968 | BO2: CBC000000000003368 | BP2: CBC000000000000575 | BQ2: CBC000000000002378 | BR2: CBC000000000004062 | BS2: CBC000000000003108 | BT2: CBC000000000002919 | BU2: CBC000000000004754 | BV2: CBC000000000001886 | BW2: CBC000000000003042 | BX2: CBC000000000003253 | BY2: CBC000000000002516 | BZ2: CBC000000000003607 | CA2: CBC000000000000906 | CB2: CBC000000000003647 | CC2: CBC000000000002436 | CD2: CBC000000000004132 | CE2: CBC000000000003439 | CF2: CBC000000000004533 | CG2: CBC000000000004211 | CH2: CBC000000000001935
A3: CBC000000000000737 | B3: CBC000000000001733 | C3: CBC000000000003086 | D3: CBC000000000001316 | E3: CBC000000000004814 | F3: CBC000000000001514 | G3: CBC000000000004930 | H3: CBC000000000004433 | I3: CBC000000000003154 | J3: CBC000000000001960 | K3: CBC000000000005417 | L3: CBC000000000001561 | M3: CBC000000000002299 | N3: CBC000000000000036 | O3: CBC000000000001893 | P3: CBC000000000005462 | Q3: CBC000000000002873 | R3: CBC000000000001457 | S3: CBC000000000001348 | T3: CBC000000000002396 | U3: CBC000000000004044 | V3: CBC000000000001563 | W3: CBC000000000004312 | X3: CBC000000000001855 | Y3: CBC000000000001235 | Z3: CBC000000000003393 | AA3: CBC000000000002126 | AB3: CBC000000000003497 | AC3: CBC000000000002766 | AD3: CBC000000000002218 | AE3: CBC000000000003162 | AF3: CBC000000000002032 | AG3: CBC000000000000977 | AH3: CBC000000000003969 | AI3: CBC000000000003415 | AJ3: CBC000000000000935 | AK3: CBC000000000000079 | AL3: CBC000000000000226 | AM3: CBC000000000004666 | AN3: CBC000000000001718 | AO3: CBC000000000005285 | AP3: CBC000000000000180 | AQ3: CBC000000000005520 | AR3: CBC000000000003478 | AS3: CBC000000000004815 | AT3: CBC000000000005250 | AU3: CBC000000000004581 | AV3: CBC000000000004696 | AW3: CBC000000000001760 | AX3: CBC000000000001897 | AY3: CBC000000000003447 | AZ3: CBC000000000004254 | BA3: CBC000000000001606 | BB3: CBC000000000003310 | BC3: CBC000000000000891 | BD3: CBC000000000002732 | BE3: CBC000000000003897 | BF3: CBC000000000000588 | BG3: CBC000000000005531 | BH3: CBC000000000002426 | BI3: CBC000000000000464 | BJ3: CBC000000000004493 | BK3: CBC000000000005373 | BL3: CBC000000000005174 | BM3: CBC000000000004112 | BN3: CBC000000000000066 | BO3: CBC000000000003380 | BP3: CBC000000000001537 | BQ3: CBC000000000002380 | BR3: CBC000000000004360 | BS3: CBC000000000004032 | BT3: CBC000000000002897 | BU3: CBC000000000002384 | BV3: CBC000000000001113 | BW3: CBC000000000002847 | BX3: CBC000000000003254 | BY3: CBC000000000002019 | BZ3: CBC000000000003825 | CA3: CBC000000000000640 | CB3: CBC000000000004681 | CC3: CBC000000000005049 | CD3: CBC000000000004164 | CE3: CBC000000000003384 | CF3: CBC000000000002452 | CG3: CBC000000000005510 | CH3: CBC000000000002529
A4: CBC000000000000739 | B4: CBC000000000001761 | C4: CBC000000000004858 | D4: CBC000000000001469 | E4: CBC000000000003717 | F4: CBC000000000003646 | G4: CBC000000000004931 | H4: CBC000000000004441 | I4: CBC000000000003710 | J4: CBC000000000000883 | K4: CBC000000000003065 | L4: CBC000000000001560 | M4: CBC000000000003113 | N4: CBC000000000000037 | O4: CBC000000000002591 | P4: CBC000000000003484 | Q4: CBC000000000002214 | R4: CBC000000000001553 | S4: CBC000000000000762 | T4: CBC000000000001907 | U4: CBC000000000003672 | V4: CBC000000000001031 | W4: CBC000000000003487 | X4: CBC000000000005125 | Y4: CBC000000000005403 | Z4: CBC000000000004210 | AA4: CBC000000000002135 | AB4: CBC000000000002229 | AC4: CBC000000000003889 | AD4: CBC000000000003391 | AE4: CBC000000000002580 | AF4: CBC000000000003010 | AG4: CBC000000000001488 | AH4: CBC000000000002920 | AI4: CBC000000000003408 | AJ4: CBC000000000000931 | AK4: CBC000000000000080 | AL4: CBC000000000001799 | AM4: CBC000000000004577 | AN4: CBC000000000001557 | AO4: CBC000000000005297 | AP4: CBC000000000003313 | AQ4: CBC000000000004714 | AR4: CBC000000000003235 | AS4: CBC000000000004788 | AT4: CBC000000000003814 | AU4: CBC000000000004861 | AV4: CBC000000000004975 | AW4: CBC000000000000802 | AX4: CBC000000000003047 | AY4: CBC000000000001091 | AZ4: CBC000000000003075 | BA4: CBC000000000001630 | BB4: CBC000000000002448 | BC4: CBC000000000004693 | BD4: CBC000000000000884 | BE4: CBC000000000004287 | BF4: CBC000000000004969 | BG4: CBC000000000002419 | BH4: CBC000000000005480 | BI4: CBC000000000000439 | BJ4: CBC000000000004494 | BK4: CBC000000000005370 | BL4: CBC000000000004952 | BM4: CBC000000000005539 | BN4: CBC000000000000063 | BO4: CBC000000000003530 | BP4: CBC000000000001575 | BQ4: CBC000000000002368 | BR4: CBC000000000004363 | BS4: CBC000000000004027 | BT4: CBC000000000002894 | BU4: CBC000000000004742 | BV4: CBC000000000001804 | BW4: CBC000000000003623 | BX4: CBC000000000002849 | BY4: CBC000000000002735 | BZ4: CBC000000000003836 | CA4: CBC000000000001285 | CB4: CBC000000000001082 | CC4: CBC000000000005263 | CD4: CBC000000000004145 | CE4: CBC000000000003400 | CF4: CBC000000000002455 | CG4: CBC000000000004538 | CH4: CBC000000000002838
A5: CBC000000000004130 | B5: CBC000000000001762 | C5: CBC000000000003117 | D5: CBC000000000001397 | E5: CBC000000000004338 | F5: CBC000000000001548 | G5: CBC000000000004932 | H5: CBC000000000003866 | I5: CBC000000000002751 | J5: CBC000000000001950 | K5: CBC000000000004896 | L5: CBC000000000003665 | M5: CBC000000000002609 | N5: CBC000000000005124 | O5: CBC000000000002582 | P5: CBC000000000002750 | Q5: CBC000000000004335 | R5: CBC000000000001874 | S5: CBC000000000001768 | T5: CBC000000000001512 | U5: CBC000000000004037 | V5: CBC000000000001787 | W5: CBC000000000003527 | X5: CBC000000000000013 | Y5: CBC000000000005412 | Z5: CBC000000000001968 | AA5: CBC000000000002162 | AB5: CBC000000000002222 | AC5: CBC000000000003890 | AD5: CBC000000000003243 | AE5: CBC000000000002034 | AF5: CBC000000000003016 | AG5: CBC000000000000814 | AH5: CBC000000000002071 | AI5: CBC000000000004009 | AJ5: CBC000000000005103 | AK5: CBC000000000000083 | AL5: CBC000000000005452 | AM5: CBC000000000003282 | AN5: CBC000000000002208 | AO5: CBC000000000002275 | AP5: CBC000000000003206 | AQ5: CBC000000000004184 | AR5: CBC000000000001246 | AS5: CBC000000000004774 | AT5: CBC000000000004074 | AU5: CBC000000000004624 | AV5: CBC000000000004636 | AW5: CBC000000000000842 | AX5: CBC000000000002189 | AY5: CBC000000000001660 | AZ5: CBC000000000002770 | BA5: CBC000000000004203 | BB5: CBC000000000002874 | BC5: CBC000000000000438 | BD5: CBC000000000002459 | BE5: CBC000000000003548 | BF5: CBC000000000000617 | BG5: CBC000000000002420 | BH5: CBC000000000005153 | BI5: CBC000000000000429 | BJ5: CBC000000000004489 | BK5: CBC000000000005243 | BL5: CBC000000000005175 | BM5: CBC000000000004790 | BN5: CBC000000000000067 | BO5: CBC000000000005109 | BP5: CBC000000000000435 | BQ5: CBC000000000002355 | BR5: CBC000000000004460 | BS5: CBC000000000005018 | BT5: CBC000000000002898 | BU5: CBC000000000004739 | BV5: CBC000000000001808 | BW5: CBC000000000002858 | BX5: CBC000000000002883 | BY5: CBC000000000002057 | BZ5: CBC000000000003742 | CA5: CBC000000000000913 | CB5: CBC000000000001508 | CC5: CBC000000000002330 | CD5: CBC000000000004128 | CE5: CBC000000000003374 | CF5: CBC000000000002458 | CG5: CBC000000000000355 | CH5: CBC000000000003260
A6: CBC000000000000741 | B6: CBC000000000000649 | C6: CBC000000000004830 | D6: CBC000000000001367 | E6: CBC000000000004237 | F6: CBC000000000001529 | G6: CBC000000000004933 | H6: CBC000000000004423 | I6: CBC000000000002686 | J6: CBC000000000005338 | K6: CBC000000000005254 | L6: CBC000000000002117 | M6: CBC000000000003115 | N6: CBC000000000005155 | O6: CBC000000000002599 | P6: CBC000000000003783 | Q6: CBC000000000005388 | R6: CBC000000000001884 | S6: CBC000000000001717 | T6: CBC000000000002398 | U6: CBC000000000003650 | V6: CBC000000000001389 | W6: CBC000000000003519 | X6: CBC000000000000028 | Y6: CBC000000000000633 | Z6: CBC000000000002716 | AA6: CBC000000000002157 | AB6: CBC000000000002223 | AC6: CBC000000000003891 | AD6: CBC000000000005095 | AE6: CBC000000000002659 | AF6: CBC000000000003018 | AG6: CBC000000000000895 | AH6: CBC000000000003751 | AI6: CBC000000000004201 | AJ6: CBC000000000000947 | AK6: CBC000000000000088 | AL6: CBC000000000005457 | AM6: CBC000000000004954 | AN6: CBC000000000001859 | AO6: CBC000000000002273 | AP6: CBC000000000003208 | AQ6: CBC000000000003351 | AR6: CBC000000000002414 | AS6: CBC000000000004768 | AT6: CBC000000000003849 | AU6: CBC000000000004276 | AV6: CBC000000000004105 | AW6: CBC000000000001766 | AX6: CBC000000000002188 | AY6: CBC000000000001515 | AZ6: CBC000000000004393 | BA6: CBC000000000002166 | BB6: CBC000000000001980 | BC6: CBC000000000000486 | BD6: CBC000000000001770 | BE6: CBC000000000003780 | BF6: CBC000000000002327 | BG6: CBC000000000002402 | BH6: CBC000000000003512 | BI6: CBC000000000000516 | BJ6: CBC000000000004456 | BK6: CBC000000000005244 | BL6: CBC000000000004893 | BM6: CBC000000000003503 | BN6: CBC000000000000069 | BO6: CBC000000000003385 | BP6: CBC000000000000619 | BQ6: CBC000000000002381 | BR6: CBC000000000004480 | BS6: CBC000000000003698 | BT6: CBC000000000002902 | BU6: CBC000000000004755 | BV6: CBC000000000001706 | BW6: CBC000000000004087 | BX6: CBC000000000003239 | BY6: CBC000000000002553 | BZ6: CBC000000000003839 | CA6: CBC000000000000920 | CB6: CBC000000000000701 | CC6: CBC000000000003671 | CD6: CBC000000000004116 | CE6: CBC000000000003375 | CF6: CBC000000000002491 | CG6: CBC000000000000367 | CH6: CBC000000000001866
A7: CBC000000000000744 | B7: CBC000000000001783 | C7: CBC000000000004827 | D7: CBC000000000000991 | E7: CBC000000000004750 | F7: CBC000000000004951 | G7: CBC000000000004934 | H7: CBC000000000004427 | I7: CBC000000000002678 | J7: CBC000000000001957 | K7: CBC000000000002818 | L7: CBC000000000002268 | M7: CBC000000000003122 | N7: CBC000000000000040 | O7: CBC000000000001800 | P7: CBC000000000004897 | Q7: CBC000000000002793 | R7: CBC000000000001295 | S7: CBC000000000001333 | T7: CBC000000000001507 | U7: CBC000000000003649 | V7: CBC000000000001725 | W7: CBC000000000002979 | X7: CBC000000000001946 | Y7: CBC000000000000607 | Z7: CBC000000000002560 | AA7: CBC000000000002154 | AB7: CBC000000000002224 | AC7: CBC000000000003886 | AD7: CBC000000000005298 | AE7: CBC000000000002573 | AF7: CBC000000000003019 | AG7: CBC000000000000728 | AH7: CBC000000000002942 | AI7: CBC000000000003353 | AJ7: CBC000000000005327 | AK7: CBC000000000000090 | AL7: CBC000000000005481 | AM7: CBC000000000004569 | AN7: CBC000000000001948 | AO7: CBC000000000002282 | AP7: CBC000000000000177 | AQ7: CBC000000000004190 | AR7: CBC000000000001608 | AS7: CBC000000000004430 | AT7: CBC000000000003772 | AU7: CBC000000000004607 | AV7: CBC000000000004639 | AW7: CBC000000000001833 | AX7: CBC000000000000792 | AY7: CBC000000000001260 | AZ7: CBC000000000002778 | BA7: CBC000000000001534 | BB7: CBC000000000003427 | BC7: CBC000000000000285 | BD7: CBC000000000004829 | BE7: CBC000000000003550 | BF7: CBC000000000005007 | BG7: CBC000000000002841 | BH7: CBC000000000003702 | BI7: CBC000000000005056 | BJ7: CBC000000000005387 | BK7: CBC000000000004394 | BL7: CBC000000000004583 | BM7: CBC000000000003634 | BN7: CBC000000000000074 | BO7: CBC000000000003964 | BP7: CBC000000000001861 | BQ7: CBC000000000002359 | BR7: CBC000000000005221 | BS7: CBC000000000003699 | BT7: CBC000000000002903 | BU7: CBC000000000004751 | BV7: CBC000000000001085 | BW7: CBC000000000004101 | BX7: CBC000000000003496 | BY7: CBC000000000002100 | BZ7: CBC000000000004198 | CA7: CBC000000000003628 | CB7: CBC000000000001449 | CC7: CBC000000000003068 | CD7: CBC000000000004136 | CE7: CBC000000000003003 | CF7: CBC000000000002464 | CG7: CBC000000000001169 | CH7: CBC000000000000760
A8: CBC000000000000748 | B8: CBC000000000002095 | C8: CBC000000000004076 | D8: CBC000000000001180 | E8: CBC000000000002650 | F8: CBC000000000001522 | G8: CBC000000000004929 | H8: CBC000000000004439 | I8: CBC000000000002684 | J8: CBC000000000005332 | K8: CBC000000000005394 | L8: CBC000000000002266 | M8: CBC000000000003175 | N8: CBC000000000000041 | O8: CBC000000000004367 | P8: CBC000000000004879 | Q8: CBC000000000005316 | R8: CBC000000000001309 | S8: CBC000000000001495 | T8: CBC000000000002399 | U8: CBC000000000002416 | V8: CBC000000000001395 | W8: CBC000000000005283 | X8: CBC000000000004214 | Y8: CBC000000000000627 | Z8: CBC000000000002562 | AA8: CBC000000000003312 | AB8: CBC000000000002225 | AC8: CBC000000000002091 | AD8: CBC000000000002910 | AE8: CBC000000000002731 | AF8: CBC000000000003021 | AG8: CBC000000000001723 | AH8: CBC000000000002993 | AI8: CBC000000000003459 | AJ8: CBC000000000004839 | AK8: CBC000000000000126 | AL8: CBC000000000005483 | AM8: CBC000000000005062 | AN8: CBC000000000002109 | AO8: CBC000000000002298 | AP8: CBC000000000003314 | AQ8: CBC000000000004187 | AR8: CBC000000000005382 | AS8: CBC000000000003645 | AT8: CBC000000000004843 | AU8: CBC000000000004737 | AV8: CBC000000000004110 | AW8: CBC000000000001836 | AX8: CBC000000000000841 | AY8: CBC000000000001220 | AZ8: CBC000000000002819 | BA8: CBC000000000001696 | BB8: CBC000000000003892 | BC8: CBC000000000000310 | BD8: CBC000000000000846 | BE8: CBC000000000004429 | BF8: CBC000000000004997 | BG8: CBC000000000005525 | BH8: CBC000000000003185 | BI8: CBC000000000004387 | BJ8: CBC000000000004485 | BK8: CBC000000000005371 | BL8: CBC000000000004884 | BM8: CBC000000000003371 | BN8: CBC000000000003986 | BO8: CBC000000000003542 | BP8: CBC000000000000445 | BQ8: CBC000000000002338 | BR8: CBC000000000004461 | BS8: CBC000000000004736 | BT8: CBC000000000002928 | BU8: CBC000000000002382 | BV8: CBC000000000001409 | BW8: CBC000000000002861 | BX8: CBC000000000002272 | BY8: CBC000000000002550 | BZ8: CBC000000000003837 | CA8: CBC000000000000738 | CB8: CBC000000000004523 | CC8: CBC000000000002318 | CD8: CBC000000000004141 | CE8: CBC000000000002159 | CF8: CBC000000000002496 | CG8: CBC000000000000968 | CH8: CBC000000000000772
A9: CBC000000000003469 | B9: CBC000000000001182 | C9: CBC000000000004088 | D9: CBC000000000001406 | E9: CBC000000000004894 | F9: CBC000000000001536 | G9: CBC000000000004935 | H9: CBC000000000004434 | I9: CBC000000000003140 | J9: CBC000000000001899 | K9: CBC000000000004677 | L9: CBC000000000001562 | M9: CBC000000000003146 | N9: CBC000000000005193 | O9: CBC000000000002592 | P9: CBC000000000003787 | Q9: CBC000000000002066 | R9: CBC000000000001320 | S9: CBC000000000000936 | T9: CBC000000000001478 | U9: CBC000000000003674 | V9: CBC000000000001359 | W9: CBC000000000004966 | X9: CBC000000000005389 | Z9: CBC000000000002206 | AA9: CBC000000000002163 | AB9: CBC000000000002226 | AC9: CBC000000000004040 | AD9: CBC000000000002824 | AE9: CBC000000000002729 | AF9: CBC000000000003025 | AG9: CBC000000000000585 | AH9: CBC000000000002938 | AJ9: CBC000000000005158 | AK9: CBC000000000000102 | AL9: CBC000000000005487 | AM9: CBC000000000005088 | AN9: CBC000000000001930 | AO9: CBC000000000002279 | AP9: CBC000000000000172 | AQ9: CBC000000000004179 | AR9: CBC000000000001162 | AS9: CBC000000000003648 | AT9: CBC000000000003798 | AU9: CBC000000000003920 | AV9: CBC000000000004697 | AW9: CBC000000000001853 | AX9: CBC000000000002191 | AY9: CBC000000000001214 | AZ9: CBC000000000002862 | BA9: CBC000000000001576 | BB9: CBC000000000002878 | BC9: CBC000000000000273 | BD9: CBC000000000002713 | BE9: CBC000000000003657 | BF9: CBC000000000003229 | BG9: CBC000000000003612 | BH9: CBC000000000004854 | BI9: CBC000000000000582 | BJ9: CBC000000000004491 | BK9: CBC000000000004741 | BL9: CBC000000000004584 | BM9: CBC000000000003232 | BN9: CBC000000000000077 | BO9: CBC000000000003073 | BP9: CBC000000000001981 | BQ9: CBC000000000002372 | BR9: CBC000000000005225 | BS9: CBC000000000004740 | BT9: CBC000000000003102 | BU9: CBC000000000000632 | BV9: CBC000000000001903 | BW9: CBC000000000002864 | BX9: CBC000000000005293 | BY9: CBC000000000002301 | BZ9: CBC000000000003248 | CA9: CBC000000000003633 | CB9: CBC000000000000717 | CC9: CBC000000000002328 | CD9: CBC000000000004168 | CE9: CBC000000000003528 | CF9: CBC000000000002460 | CG9: CBC000000000000524 | CH9: CBC000000000000325
A10: CBC000000000004129 | B10: CBC000000000003245 | C10: CBC000000000004797 | D10: CBC000000000001335 | E10: CBC000000000004773 | F10: CBC000000000001540 | G10: CBC000000000004938 | H10: CBC000000000004165 | I10: CBC000000000003160 | J10: CBC000000000000880 | K10: CBC000000000002804 | L10: CBC000000000004197 | M10: CBC000000000003449 | N10: CBC000000000000565 | O10: CBC000000000001801 | P10: CBC000000000003789 | Q10: CBC000000000004617 | R10: CBC000000000001376 | S10: CBC000000000001902 | T10: CBC000000000001523 | U10: CBC000000000003675 | V10: CBC000000000001102 | W10: CBC000000000005303 | X10: CBC000000000005191 | Z10: CBC000000000002865 | AA10: CBC000000000002127 | AB10: CBC000000000002228 | AC10: CBC000000000002083 | AD10: CBC000000000004059 | AE10: CBC000000000002570 | AF10: CBC000000000003028 | AG10: CBC000000000004272 | AH10: CBC000000000003975 | AJ10: CBC000000000005330 | AK10: CBC000000000000103 | AL10: CBC000000000005491 | AM10: CBC000000000004552 | AN10: CBC000000000001798 | AO10: CBC000000000002296 | AP10: CBC000000000000163 | AQ10: CBC000000000004837 | AR10: CBC000000000001278 | AS10: CBC000000000004401 | AT10: CBC000000000003800 | AU10: CBC000000000004730 | AV10: CBC000000000004976 | AW10: CBC000000000000888 | AX10: CBC000000000001004 | AY10: CBC000000000001262 | AZ10: CBC000000000004404 | BA10: CBC000000000001545 | BB10: CBC000000000002467 | BC10: CBC000000000000261 | BD10: CBC000000000002724 | BE10: CBC000000000003807 | BF10: CBC000000000003241 | BG10: CBC000000000005548 | BH10: CBC000000000004616 | BI10: CBC000000000005055 | BJ10: CBC000000000004490 | BK10: CBC000000000004002 | BL10: CBC000000000004587 | BM10: CBC000000000005418 | BN10: CBC000000000000365 | BO10: CBC000000000003414 | BP10: CBC000000000000504 | BQ10: CBC000000000002365 | BR10: CBC000000000004376 | BS10: CBC000000000003940 | BT10: CBC000000000002904 | BU10: CBC000000000000638 | BV10: CBC000000000001426 | BW10: CBC000000000003620 | BX10: CBC000000000005296 | BY10: CBC000000000003318 | BZ10: CBC000000000003830 | CA10: CBC000000000000448 | CB10: CBC000000000000821 | CC10: CBC000000000002310 | CD10: CBC000000000004177 | CE10: CBC000000000003386 | CF10: CBC000000000002481 | CG10: CBC000000000005067 | CH10: CBC000000000000364
A11: CBC000000000000754 | B11: CBC000000000001772 | C11: CBC000000000003262 | D11: CBC000000000001336 | E11: CBC000000000004820 | F11: CBC000000000001543 | G11: CBC000000000004939 | H11: CBC000000000004183 | I11: CBC000000000003165 | J11: CBC000000000001953 | K11: CBC000000000005434 | L11: CBC000000000001589 | M11: CBC000000000003136 | N11: CBC000000000005428 | O11: CBC000000000002572 | P11: CBC000000000003795 | Q11: CBC000000000002530 | R11: CBC000000000001399 | S11: CBC000000000001904 | T11: CBC000000000003784 | U11: CBC000000000002703 | V11: CBC000000000001034 | W11: CBC000000000002690 | X11: CBC000000000005374 | Z11: CBC000000000002544 | AA11: CBC000000000002131 | AB11: CBC000000000002230 | AC11: CBC000000000002093 | AD11: CBC000000000004072 | AE11: CBC000000000002726 | AF11: CBC000000000002096 | AG11: CBC000000000000643 | AH11: CBC000000000003761 | AJ11: CBC000000000004948 | AK11: CBC000000000000108 | AL11: CBC000000000005454 | AM11: CBC000000000005211 | AN11: CBC000000000002633 | AO11: CBC000000000005278 | AP11: CBC000000000000157 | AQ11: CBC000000000004253 | AR11: CBC000000000001604 | AS11: CBC000000000004573 | AT11: CBC000000000003803 | AU11: CBC000000000004213 | AV11: CBC000000000004285 | AW11: CBC000000000003716 | AX11: CBC000000000001024 | AY11: CBC000000000001267 | AZ11: CBC000000000003935 | BA11: CBC000000000001625 | BB11: CBC000000000003505 | BC11: CBC000000000000278 | BD11: CBC000000000002465 | BE11: CBC000000000004821 | BF11: CBC000000000003227 | BG11: CBC000000000004571 | BH11: CBC000000000004648 | BI11: CBC000000000000599 | BJ11: CBC000000000004911 | BK11: CBC000000000004146 | BL11: CBC000000000004618 | BM11: CBC000000000004067 | BN11: CBC000000000003389 | BO11: CBC000000000003515 | BQ11: CBC000000000002341 | BR11: CBC000000000004156 | BS11: CBC000000000002893 | BT11: CBC000000000002906 | BU11: CBC000000000002014 | BV11: CBC000000000001417 | BW11: CBC000000000002867 | BX11: CBC000000000002583 | BY11: CBC000000000002302 | BZ11: CBC000000000003777 | CA11: CBC000000000000665 | CB11: CBC000000000000673 | CC11: CBC000000000005039 | CD11: CBC000000000004174 | CE11: CBC000000000003493 | CF11: CBC000000000002470 | CG11: CBC000000000001270 | CH11: CBC000000000000555
A12: CBC000000000004131 | B12: CBC000000000001769 | C12: CBC000000000003249 | D12: CBC000000000001339 | E12: CBC000000000004868 | G12: CBC000000000004928 | H12: CBC000000000003872 | I12: CBC000000000003167 | J12: CBC000000000001781 | K12: CBC000000000005503 | L12: CBC000000000001564 | N12: CBC000000000001754 | O12: CBC000000000001649 | P12: CBC000000000003813 | Q12: CBC000000000004436 | R12: CBC000000000001407 | S12: CBC000000000001905 | T12: CBC000000000003792 | U12: CBC000000000003677 | V12: CBC000000000001721 | W12: CBC000000000002954 | X12: CBC000000000005306 | Z12: CBC000000000003879 | AA12: CBC000000000002158 | AB12: CBC000000000002231 | AC12: CBC000000000002073 | AD12: CBC000000000004389 | AE12: CBC000000000002655 | AF12: CBC000000000002039 | AG12: CBC000000000001702 | AH12: CBC000000000002926 | AJ12: CBC000000000005336 | AK12: CBC000000000000110 | AL12: CBC000000000000100 | AM12: CBC000000000005063 | AN12: CBC000000000002106 | AO12: CBC000000000005284 | AP12: CBC000000000003189 | AQ12: CBC000000000004958 | AR12: CBC000000000001173 | AS12: CBC000000000004803 | AT12: CBC000000000003419 | AU12: CBC000000000003929 | AV12: CBC000000000004640 | AW12: CBC000000000000896 | AX12: CBC000000000001000 | AY12: CBC000000000001254 | AZ12: CBC000000000003939 | BA12: CBC000000000004598 | BB12: CBC000000000002739 | BC12: CBC000000000000447 | BD12: CBC000000000002167 | BE12: CBC000000000004570 | BF12: CBC000000000002313 | BG12: CBC000000000005546 | BH12: CBC000000000005498 | BI12: CBC000000000001827 | BJ12: CBC000000000004910 | BK12: CBC000000000005245 | BL12: CBC000000000005176 | BM12: CBC000000000002449 | BN12: CBC000000000000312 | BO12: CBC000000000003537 | BQ12: CBC000000000002364 | BR12: CBC000000000005230 | BS12: CBC000000000003026 | BT12: CBC000000000003104 | BU12: CBC000000000000636 | BV12: CBC000000000001906 | BW12: CBC000000000004091 | BX12: CBC000000000003592 | BY12: CBC000000000002444 | BZ12: CBC000000000003781 | CA12: CBC000000000000600 | CB12: CBC000000000001118 | CC12: CBC000000000002505 | CD12: CBC000000000004180 | CE12: CBC000000000003535 | CF12: CBC000000000002473 | CG12: CBC000000000004926 | CH12: CBC000000000001146
A13: CBC000000000000759 | B13: CBC000000000002200 | C13: CBC000000000004775 | D13: CBC000000000001342 | E13: CBC000000000004361 | G13: CBC000000000004940 | H13: CBC000000000004155 | I13: CBC000000000003954 | J13: CBC000000000000921 | K13: CBC000000000005420 | L13: CBC000000000001568 | N13: CBC000000000000039 | O13: CBC000000000002525 | P13: CBC000000000004891 | Q13: CBC000000000002011 | R13: CBC000000000001411 | S13: CBC000000000002425 | T13: CBC000000000001909 | U13: CBC000000000003678 | V13: CBC000000000001301 | W13: CBC000000000005184 | X13: CBC000000000001985 | Z13: CBC000000000005569 | AA13: CBC000000000002130 | AB13: CBC000000000002232 | AC13: CBC000000000002227 | AD13: CBC000000000002826 | AE13: CBC000000000002667 | AF13: CBC000000000004521 | AG13: CBC000000000000608 | AH13: CBC000000000004848 | AJ13: CBC000000000004918 | AK13: CBC000000000000116 | AL13: CBC000000000000130 | AM13: CBC000000000004371 | AN13: CBC000000000002665 | AO13: CBC000000000004119 | AP13: CBC000000000000154 | AQ13: CBC000000000004920 | AR13: CBC000000000001126 | AS13: CBC000000000004799 | AT13: CBC000000000004835 | AU13: CBC000000000004777 | AV13: CBC000000000004315 | AW13: CBC000000000000898 | AX13: CBC000000000001010 | AY13: CBC000000000001204 | AZ13: CBC000000000003910 | BA13: CBC000000000001524 | BB13: CBC000000000003194 | BC13: CBC000000000000457 | BD13: CBC000000000002439 | BE13: CBC000000000003552 | BF13: CBC000000000004995 | BG13: CBC000000000002329 | BH13: CBC000000000003179 | BI13: CBC000000000000578 | BJ13: CBC000000000003666 | BK13: CBC000000000004688 | BL13: CBC000000000004840 | BN13: CBC000000000000082 | BO13: CBC000000000003524 | BQ13: CBC000000000004973 | BR13: CBC000000000004157 | BS13: CBC000000000004021 | BT13: CBC000000000003173 | BU13: CBC000000000002030 | BV13: CBC000000000001435 | BW13: CBC000000000003087 | BX13: CBC000000000003595 | BY13: CBC000000000001964 | BZ13: CBC000000000003786 | CA13: CBC000000000000647 | CB13: CBC000000000005024 | CC13: CBC000000000005099 | CD13: CBC000000000004169 | CE13: CBC000000000003432 | CF13: CBC000000000002469 | CG13: CBC000000000000956 | CH13: CBC000000000000757
